[2025-10-20T18:03:36.916+0000] {local_task_job_runner.py:120} INFO - ::group::Pre task execution logs
[2025-10-20T18:03:36.955+0000] {taskinstance.py:2076} INFO - Dependencies all met for dep_context=non-requeueable deps ti=<TaskInstance: produce_json.get_video_ids scheduled__2025-10-19T14:00:00+00:00 [queued]>
[2025-10-20T18:03:36.967+0000] {taskinstance.py:2076} INFO - Dependencies all met for dep_context=requeueable deps ti=<TaskInstance: produce_json.get_video_ids scheduled__2025-10-19T14:00:00+00:00 [queued]>
[2025-10-20T18:03:36.968+0000] {taskinstance.py:2306} INFO - Starting attempt 1 of 1
[2025-10-20T18:03:36.986+0000] {taskinstance.py:2330} INFO - Executing <Task(_PythonDecoratedOperator): get_video_ids> on 2025-10-19 14:00:00+00:00
[2025-10-20T18:03:36.992+0000] {standard_task_runner.py:63} INFO - Started process 528 to run task
[2025-10-20T18:03:36.998+0000] {standard_task_runner.py:90} INFO - Running: ['airflow', 'tasks', 'run', 'produce_json', 'get_video_ids', 'scheduled__2025-10-19T14:00:00+00:00', '--job-id', '10', '--raw', '--subdir', 'DAGS_FOLDER/main.py', '--cfg-path', '/tmp/tmpjk98h7kg']
[2025-10-20T18:03:37.000+0000] {standard_task_runner.py:91} INFO - Job 10: Subtask get_video_ids
[2025-10-20T18:03:37.097+0000] {task_command.py:426} INFO - Running <TaskInstance: produce_json.get_video_ids scheduled__2025-10-19T14:00:00+00:00 [running]> on host ddff07f854c7
[2025-10-20T18:03:37.248+0000] {taskinstance.py:2648} INFO - Exporting env vars: AIRFLOW_CTX_DAG_EMAIL='gidiboateng200@gmail.com' AIRFLOW_CTX_DAG_OWNER='dataengineers' AIRFLOW_CTX_DAG_ID='produce_json' AIRFLOW_CTX_TASK_ID='get_video_ids' AIRFLOW_CTX_EXECUTION_DATE='2025-10-19T14:00:00+00:00' AIRFLOW_CTX_TRY_NUMBER='1' AIRFLOW_CTX_DAG_RUN_ID='scheduled__2025-10-19T14:00:00+00:00'
[2025-10-20T18:03:37.251+0000] {taskinstance.py:430} INFO - ::endgroup::
[2025-10-20T18:05:11.682+0000] {taskinstance.py:441} INFO - ::group::Post task execution logs
[2025-10-20T18:05:11.700+0000] {taskinstance.py:2905} ERROR - Task failed with exception
Traceback (most recent call last):
  File "/home/airflow/.local/lib/python3.10/site-packages/urllib3/connectionpool.py", line 467, in _make_request
    self._validate_conn(conn)
  File "/home/airflow/.local/lib/python3.10/site-packages/urllib3/connectionpool.py", line 1099, in _validate_conn
    conn.connect()
  File "/home/airflow/.local/lib/python3.10/site-packages/urllib3/connection.py", line 653, in connect
    sock_and_verified = _ssl_wrap_socket_and_match_hostname(
  File "/home/airflow/.local/lib/python3.10/site-packages/urllib3/connection.py", line 806, in _ssl_wrap_socket_and_match_hostname
    ssl_sock = ssl_wrap_socket(
  File "/home/airflow/.local/lib/python3.10/site-packages/urllib3/util/ssl_.py", line 465, in ssl_wrap_socket
    ssl_sock = _ssl_wrap_socket_impl(sock, context, tls_in_tls, server_hostname)
  File "/home/airflow/.local/lib/python3.10/site-packages/urllib3/util/ssl_.py", line 509, in _ssl_wrap_socket_impl
    return ssl_context.wrap_socket(sock, server_hostname=server_hostname)
  File "/usr/local/lib/python3.10/ssl.py", line 513, in wrap_socket
    return self.sslsocket_class._create(
  File "/usr/local/lib/python3.10/ssl.py", line 1104, in _create
    self.do_handshake()
  File "/usr/local/lib/python3.10/ssl.py", line 1375, in do_handshake
    self._sslobj.do_handshake()
ssl.SSLEOFError: [SSL: UNEXPECTED_EOF_WHILE_READING] EOF occurred in violation of protocol (_ssl.c:1007)

During handling of the above exception, another exception occurred:

Traceback (most recent call last):
  File "/home/airflow/.local/lib/python3.10/site-packages/urllib3/connectionpool.py", line 793, in urlopen
    response = self._make_request(
  File "/home/airflow/.local/lib/python3.10/site-packages/urllib3/connectionpool.py", line 491, in _make_request
    raise new_e
urllib3.exceptions.SSLError: [SSL: UNEXPECTED_EOF_WHILE_READING] EOF occurred in violation of protocol (_ssl.c:1007)

The above exception was the direct cause of the following exception:

Traceback (most recent call last):
  File "/home/airflow/.local/lib/python3.10/site-packages/requests/adapters.py", line 486, in send
    resp = conn.urlopen(
  File "/home/airflow/.local/lib/python3.10/site-packages/urllib3/connectionpool.py", line 847, in urlopen
    retries = retries.increment(
  File "/home/airflow/.local/lib/python3.10/site-packages/urllib3/util/retry.py", line 515, in increment
    raise MaxRetryError(_pool, url, reason) from reason  # type: ignore[arg-type]
urllib3.exceptions.MaxRetryError: HTTPSConnectionPool(host='youtube.googleapis.com', port=443): Max retries exceeded with url: /youtube/v3/playlistItems?part=contentDetails&playlistId=UUX6OQ3DkcsbYNE6H8uQQuVA&key=***&maxResults=50&pageToken=EAAaH1BUOkNJUUhJaEEyTWpBNE9VUkZNVVpFUWtFMVFqWkY (Caused by SSLError(SSLEOFError(8, '[SSL: UNEXPECTED_EOF_WHILE_READING] EOF occurred in violation of protocol (_ssl.c:1007)')))

During handling of the above exception, another exception occurred:

Traceback (most recent call last):
  File "/home/airflow/.local/lib/python3.10/site-packages/airflow/models/taskinstance.py", line 465, in _execute_task
    result = _execute_callable(context=context, **execute_callable_kwargs)
  File "/home/airflow/.local/lib/python3.10/site-packages/airflow/models/taskinstance.py", line 432, in _execute_callable
    return execute_callable(context=context, **execute_callable_kwargs)
  File "/home/airflow/.local/lib/python3.10/site-packages/airflow/models/baseoperator.py", line 401, in wrapper
    return func(self, *args, **kwargs)
  File "/home/airflow/.local/lib/python3.10/site-packages/airflow/decorators/base.py", line 265, in execute
    return_value = super().execute(context)
  File "/home/airflow/.local/lib/python3.10/site-packages/airflow/models/baseoperator.py", line 401, in wrapper
    return func(self, *args, **kwargs)
  File "/home/airflow/.local/lib/python3.10/site-packages/airflow/operators/python.py", line 235, in execute
    return_value = self.execute_callable()
  File "/home/airflow/.local/lib/python3.10/site-packages/airflow/operators/python.py", line 252, in execute_callable
    return self.python_callable(*self.op_args, **self.op_kwargs)
  File "/opt/airflow/dags/api/video_stats.py", line 59, in get_video_ids
    raise e
  File "/opt/airflow/dags/api/video_stats.py", line 47, in get_video_ids
    response = requests.get(url)
  File "/home/airflow/.local/lib/python3.10/site-packages/requests/api.py", line 73, in get
    return request("get", url, params=params, **kwargs)
  File "/home/airflow/.local/lib/python3.10/site-packages/requests/api.py", line 59, in request
    return session.request(method=method, url=url, **kwargs)
  File "/home/airflow/.local/lib/python3.10/site-packages/requests/sessions.py", line 589, in request
    resp = self.send(prep, **send_kwargs)
  File "/home/airflow/.local/lib/python3.10/site-packages/requests/sessions.py", line 703, in send
    r = adapter.send(request, **kwargs)
  File "/home/airflow/.local/lib/python3.10/site-packages/requests/adapters.py", line 517, in send
    raise SSLError(e, request=request)
requests.exceptions.SSLError: HTTPSConnectionPool(host='youtube.googleapis.com', port=443): Max retries exceeded with url: /youtube/v3/playlistItems?part=contentDetails&playlistId=UUX6OQ3DkcsbYNE6H8uQQuVA&key=***&maxResults=50&pageToken=EAAaH1BUOkNJUUhJaEEyTWpBNE9VUkZNVVpFUWtFMVFqWkY (Caused by SSLError(SSLEOFError(8, '[SSL: UNEXPECTED_EOF_WHILE_READING] EOF occurred in violation of protocol (_ssl.c:1007)')))
[2025-10-20T18:05:11.802+0000] {taskinstance.py:1206} INFO - Marking task as FAILED. dag_id=produce_json, task_id=get_video_ids, run_id=scheduled__2025-10-19T14:00:00+00:00, execution_date=20251019T140000, start_date=20251020T180336, end_date=20251020T180511
[2025-10-20T18:05:11.845+0000] {standard_task_runner.py:110} ERROR - Failed to execute job 10 for task get_video_ids (HTTPSConnectionPool(host='youtube.googleapis.com', port=443): Max retries exceeded with url: /youtube/v3/playlistItems?part=contentDetails&playlistId=UUX6OQ3DkcsbYNE6H8uQQuVA&key=***&maxResults=50&pageToken=EAAaH1BUOkNJUUhJaEEyTWpBNE9VUkZNVVpFUWtFMVFqWkY (Caused by SSLError(SSLEOFError(8, '[SSL: UNEXPECTED_EOF_WHILE_READING] EOF occurred in violation of protocol (_ssl.c:1007)'))); 528)
[2025-10-20T18:05:11.899+0000] {local_task_job_runner.py:240} INFO - Task exited with return code 1
[2025-10-20T18:05:11.974+0000] {taskinstance.py:3503} INFO - 0 downstream tasks scheduled from follow-on schedule check
[2025-10-20T18:05:11.988+0000] {local_task_job_runner.py:222} INFO - ::endgroup::
