[2025-10-22T02:35:05.180+0000] {local_task_job_runner.py:120} INFO - ::group::Pre task execution logs
[2025-10-22T02:35:05.544+0000] {taskinstance.py:2076} INFO - Dependencies all met for dep_context=non-requeueable deps ti=<TaskInstance: produce_json.get_playlist_id scheduled__2025-10-20T14:00:00+00:00 [queued]>
[2025-10-22T02:35:05.612+0000] {taskinstance.py:2076} INFO - Dependencies all met for dep_context=requeueable deps ti=<TaskInstance: produce_json.get_playlist_id scheduled__2025-10-20T14:00:00+00:00 [queued]>
[2025-10-22T02:35:05.617+0000] {taskinstance.py:2306} INFO - Starting attempt 1 of 1
[2025-10-22T02:35:05.695+0000] {taskinstance.py:2330} INFO - Executing <Task(_PythonDecoratedOperator): get_playlist_id> on 2025-10-20 14:00:00+00:00
[2025-10-22T02:35:05.742+0000] {standard_task_runner.py:63} INFO - Started process 1851 to run task
[2025-10-22T02:35:05.758+0000] {standard_task_runner.py:90} INFO - Running: ['airflow', 'tasks', 'run', 'produce_json', 'get_playlist_id', 'scheduled__2025-10-20T14:00:00+00:00', '--job-id', '16', '--raw', '--subdir', 'DAGS_FOLDER/main.py', '--cfg-path', '/tmp/tmpzn23jrja']
[2025-10-22T02:35:05.766+0000] {standard_task_runner.py:91} INFO - Job 16: Subtask get_playlist_id
[2025-10-22T02:35:06.343+0000] {task_command.py:426} INFO - Running <TaskInstance: produce_json.get_playlist_id scheduled__2025-10-20T14:00:00+00:00 [running]> on host ddff07f854c7
[2025-10-22T02:35:11.433+0000] {taskinstance.py:2648} INFO - Exporting env vars: AIRFLOW_CTX_DAG_EMAIL='gidiboateng200@gmail.com' AIRFLOW_CTX_DAG_OWNER='dataengineers' AIRFLOW_CTX_DAG_ID='produce_json' AIRFLOW_CTX_TASK_ID='get_playlist_id' AIRFLOW_CTX_EXECUTION_DATE='2025-10-20T14:00:00+00:00' AIRFLOW_CTX_TRY_NUMBER='1' AIRFLOW_CTX_DAG_RUN_ID='scheduled__2025-10-20T14:00:00+00:00'
[2025-10-22T02:35:11.439+0000] {taskinstance.py:430} INFO - ::endgroup::
[2025-10-22T02:35:12.399+0000] {taskinstance.py:441} INFO - ::group::Post task execution logs
[2025-10-22T02:35:12.406+0000] {taskinstance.py:2905} ERROR - Task failed with exception
Traceback (most recent call last):
  File "/home/airflow/.local/lib/python3.10/site-packages/urllib3/connection.py", line 198, in _new_conn
    sock = connection.create_connection(
  File "/home/airflow/.local/lib/python3.10/site-packages/urllib3/util/connection.py", line 60, in create_connection
    for res in socket.getaddrinfo(host, port, family, socket.SOCK_STREAM):
  File "/usr/local/lib/python3.10/socket.py", line 955, in getaddrinfo
    for res in _socket.getaddrinfo(host, port, family, type, proto, flags):
socket.gaierror: [Errno -2] Name or service not known

The above exception was the direct cause of the following exception:

Traceback (most recent call last):
  File "/home/airflow/.local/lib/python3.10/site-packages/urllib3/connectionpool.py", line 793, in urlopen
    response = self._make_request(
  File "/home/airflow/.local/lib/python3.10/site-packages/urllib3/connectionpool.py", line 491, in _make_request
    raise new_e
  File "/home/airflow/.local/lib/python3.10/site-packages/urllib3/connectionpool.py", line 467, in _make_request
    self._validate_conn(conn)
  File "/home/airflow/.local/lib/python3.10/site-packages/urllib3/connectionpool.py", line 1099, in _validate_conn
    conn.connect()
  File "/home/airflow/.local/lib/python3.10/site-packages/urllib3/connection.py", line 616, in connect
    self.sock = sock = self._new_conn()
  File "/home/airflow/.local/lib/python3.10/site-packages/urllib3/connection.py", line 205, in _new_conn
    raise NameResolutionError(self.host, self, e) from e
urllib3.exceptions.NameResolutionError: <urllib3.connection.HTTPSConnection object at 0x724393a33340>: Failed to resolve 'youtube.googleapis.com' ([Errno -2] Name or service not known)

The above exception was the direct cause of the following exception:

Traceback (most recent call last):
  File "/home/airflow/.local/lib/python3.10/site-packages/requests/adapters.py", line 486, in send
    resp = conn.urlopen(
  File "/home/airflow/.local/lib/python3.10/site-packages/urllib3/connectionpool.py", line 847, in urlopen
    retries = retries.increment(
  File "/home/airflow/.local/lib/python3.10/site-packages/urllib3/util/retry.py", line 515, in increment
    raise MaxRetryError(_pool, url, reason) from reason  # type: ignore[arg-type]
urllib3.exceptions.MaxRetryError: HTTPSConnectionPool(host='youtube.googleapis.com', port=443): Max retries exceeded with url: /youtube/v3/channels?part=contentDetails&forHandle=MrBeast&key=*** (Caused by NameResolutionError("<urllib3.connection.HTTPSConnection object at 0x724393a33340>: Failed to resolve 'youtube.googleapis.com' ([Errno -2] Name or service not known)"))

During handling of the above exception, another exception occurred:

Traceback (most recent call last):
  File "/home/airflow/.local/lib/python3.10/site-packages/airflow/models/taskinstance.py", line 465, in _execute_task
    result = _execute_callable(context=context, **execute_callable_kwargs)
  File "/home/airflow/.local/lib/python3.10/site-packages/airflow/models/taskinstance.py", line 432, in _execute_callable
    return execute_callable(context=context, **execute_callable_kwargs)
  File "/home/airflow/.local/lib/python3.10/site-packages/airflow/models/baseoperator.py", line 401, in wrapper
    return func(self, *args, **kwargs)
  File "/home/airflow/.local/lib/python3.10/site-packages/airflow/decorators/base.py", line 265, in execute
    return_value = super().execute(context)
  File "/home/airflow/.local/lib/python3.10/site-packages/airflow/models/baseoperator.py", line 401, in wrapper
    return func(self, *args, **kwargs)
  File "/home/airflow/.local/lib/python3.10/site-packages/airflow/operators/python.py", line 235, in execute
    return_value = self.execute_callable()
  File "/home/airflow/.local/lib/python3.10/site-packages/airflow/operators/python.py", line 252, in execute_callable
    return self.python_callable(*self.op_args, **self.op_kwargs)
  File "/opt/airflow/dags/api/video_stats.py", line 31, in get_playlist_id
    raise e
  File "/opt/airflow/dags/api/video_stats.py", line 23, in get_playlist_id
    response = requests.get(url)
  File "/home/airflow/.local/lib/python3.10/site-packages/requests/api.py", line 73, in get
    return request("get", url, params=params, **kwargs)
  File "/home/airflow/.local/lib/python3.10/site-packages/requests/api.py", line 59, in request
    return session.request(method=method, url=url, **kwargs)
  File "/home/airflow/.local/lib/python3.10/site-packages/requests/sessions.py", line 589, in request
    resp = self.send(prep, **send_kwargs)
  File "/home/airflow/.local/lib/python3.10/site-packages/requests/sessions.py", line 703, in send
    r = adapter.send(request, **kwargs)
  File "/home/airflow/.local/lib/python3.10/site-packages/requests/adapters.py", line 519, in send
    raise ConnectionError(e, request=request)
requests.exceptions.ConnectionError: HTTPSConnectionPool(host='youtube.googleapis.com', port=443): Max retries exceeded with url: /youtube/v3/channels?part=contentDetails&forHandle=MrBeast&key=*** (Caused by NameResolutionError("<urllib3.connection.HTTPSConnection object at 0x724393a33340>: Failed to resolve 'youtube.googleapis.com' ([Errno -2] Name or service not known)"))
[2025-10-22T02:35:12.770+0000] {taskinstance.py:1206} INFO - Marking task as FAILED. dag_id=produce_json, task_id=get_playlist_id, run_id=scheduled__2025-10-20T14:00:00+00:00, execution_date=20251020T140000, start_date=20251022T023505, end_date=20251022T023512
[2025-10-22T02:35:12.899+0000] {standard_task_runner.py:110} ERROR - Failed to execute job 16 for task get_playlist_id (HTTPSConnectionPool(host='youtube.googleapis.com', port=443): Max retries exceeded with url: /youtube/v3/channels?part=contentDetails&forHandle=MrBeast&key=*** (Caused by NameResolutionError("<urllib3.connection.HTTPSConnection object at 0x724393a33340>: Failed to resolve 'youtube.googleapis.com' ([Errno -2] Name or service not known)")); 1851)
[2025-10-22T02:35:12.988+0000] {local_task_job_runner.py:240} INFO - Task exited with return code 1
[2025-10-22T02:35:13.242+0000] {taskinstance.py:3503} INFO - 0 downstream tasks scheduled from follow-on schedule check
[2025-10-22T02:35:13.303+0000] {local_task_job_runner.py:222} INFO - ::endgroup::
