[2025-10-22T09:23:48.832+0000] {local_task_job_runner.py:120} INFO - ::group::Pre task execution logs
[2025-10-22T09:23:48.950+0000] {taskinstance.py:2076} INFO - Dependencies all met for dep_context=non-requeueable deps ti=<TaskInstance: update_db.staging_table scheduled__2025-10-20T15:00:00+00:00 [queued]>
[2025-10-22T09:23:48.997+0000] {taskinstance.py:2076} INFO - Dependencies all met for dep_context=requeueable deps ti=<TaskInstance: update_db.staging_table scheduled__2025-10-20T15:00:00+00:00 [queued]>
[2025-10-22T09:23:49.000+0000] {taskinstance.py:2306} INFO - Starting attempt 1 of 1
[2025-10-22T09:23:49.067+0000] {taskinstance.py:2330} INFO - Executing <Task(_PythonDecoratedOperator): staging_table> on 2025-10-20 15:00:00+00:00
[2025-10-22T09:23:49.094+0000] {standard_task_runner.py:63} INFO - Started process 4298 to run task
[2025-10-22T09:23:49.102+0000] {standard_task_runner.py:90} INFO - Running: ['airflow', 'tasks', 'run', 'update_db', 'staging_table', 'scheduled__2025-10-20T15:00:00+00:00', '--job-id', '21', '--raw', '--subdir', 'DAGS_FOLDER/main.py', '--cfg-path', '/tmp/tmpvsx6o57a']
[2025-10-22T09:23:49.109+0000] {standard_task_runner.py:91} INFO - Job 21: Subtask staging_table
[2025-10-22T09:23:49.339+0000] {task_command.py:426} INFO - Running <TaskInstance: update_db.staging_table scheduled__2025-10-20T15:00:00+00:00 [running]> on host ddff07f854c7
[2025-10-22T09:23:49.653+0000] {taskinstance.py:2648} INFO - Exporting env vars: AIRFLOW_CTX_DAG_EMAIL='gidiboateng200@gmail.com' AIRFLOW_CTX_DAG_OWNER='dataengineers' AIRFLOW_CTX_DAG_ID='update_db' AIRFLOW_CTX_TASK_ID='staging_table' AIRFLOW_CTX_EXECUTION_DATE='2025-10-20T15:00:00+00:00' AIRFLOW_CTX_TRY_NUMBER='1' AIRFLOW_CTX_DAG_RUN_ID='scheduled__2025-10-20T15:00:00+00:00'
[2025-10-22T09:23:49.664+0000] {taskinstance.py:430} INFO - ::endgroup::
[2025-10-22T09:23:49.846+0000] {base.py:84} INFO - Using connection ID 'postgres_db_yt_elt' for task execution.
[2025-10-22T09:23:49.919+0000] {dataware_house.py:44} ERROR - An error occurred during the update of staging table: 'cursfor_factory' is an invalid keyword argument for this function
[2025-10-22T09:23:49.921+0000] {taskinstance.py:441} INFO - ::group::Post task execution logs
[2025-10-22T09:23:49.925+0000] {taskinstance.py:2905} ERROR - Task failed with exception
Traceback (most recent call last):
  File "/home/airflow/.local/lib/python3.10/site-packages/airflow/models/taskinstance.py", line 465, in _execute_task
    result = _execute_callable(context=context, **execute_callable_kwargs)
  File "/home/airflow/.local/lib/python3.10/site-packages/airflow/models/taskinstance.py", line 432, in _execute_callable
    return execute_callable(context=context, **execute_callable_kwargs)
  File "/home/airflow/.local/lib/python3.10/site-packages/airflow/models/baseoperator.py", line 401, in wrapper
    return func(self, *args, **kwargs)
  File "/home/airflow/.local/lib/python3.10/site-packages/airflow/decorators/base.py", line 265, in execute
    return_value = super().execute(context)
  File "/home/airflow/.local/lib/python3.10/site-packages/airflow/models/baseoperator.py", line 401, in wrapper
    return func(self, *args, **kwargs)
  File "/home/airflow/.local/lib/python3.10/site-packages/airflow/operators/python.py", line 235, in execute
    return_value = self.execute_callable()
  File "/home/airflow/.local/lib/python3.10/site-packages/airflow/operators/python.py", line 252, in execute_callable
    return self.python_callable(*self.op_args, **self.op_kwargs)
  File "/opt/airflow/dags/datawarehouse/dataware_house.py", line 45, in staging_table
    raise e
  File "/opt/airflow/dags/datawarehouse/dataware_house.py", line 18, in staging_table
    conn, cur = get_conn_cursor()
  File "/opt/airflow/dags/datawarehouse/data_utils.py", line 9, in get_conn_cursor
    cur = conn.cursor(cursfor_factory=RealDictCursor)
TypeError: 'cursfor_factory' is an invalid keyword argument for this function
[2025-10-22T09:23:50.011+0000] {taskinstance.py:1206} INFO - Marking task as FAILED. dag_id=update_db, task_id=staging_table, run_id=scheduled__2025-10-20T15:00:00+00:00, execution_date=20251020T150000, start_date=20251022T092348, end_date=20251022T092350
[2025-10-22T09:23:50.070+0000] {standard_task_runner.py:110} ERROR - Failed to execute job 21 for task staging_table ('cursfor_factory' is an invalid keyword argument for this function; 4298)
[2025-10-22T09:23:50.148+0000] {local_task_job_runner.py:240} INFO - Task exited with return code 1
[2025-10-22T09:23:50.224+0000] {taskinstance.py:3503} INFO - 0 downstream tasks scheduled from follow-on schedule check
[2025-10-22T09:23:50.242+0000] {local_task_job_runner.py:222} INFO - ::endgroup::
