[2025-10-22T09:40:12.573+0000] {local_task_job_runner.py:120} INFO - ::group::Pre task execution logs
[2025-10-22T09:40:12.704+0000] {taskinstance.py:2076} INFO - Dependencies all met for dep_context=non-requeueable deps ti=<TaskInstance: update_db.staging_table manual__2025-10-22T09:40:06.580597+00:00 [queued]>
[2025-10-22T09:40:12.754+0000] {taskinstance.py:2076} INFO - Dependencies all met for dep_context=requeueable deps ti=<TaskInstance: update_db.staging_table manual__2025-10-22T09:40:06.580597+00:00 [queued]>
[2025-10-22T09:40:12.762+0000] {taskinstance.py:2306} INFO - Starting attempt 1 of 1
[2025-10-22T09:40:12.823+0000] {taskinstance.py:2330} INFO - Executing <Task(_PythonDecoratedOperator): staging_table> on 2025-10-22 09:40:06.580597+00:00
[2025-10-22T09:40:12.861+0000] {standard_task_runner.py:90} INFO - Running: ['airflow', 'tasks', 'run', 'update_db', 'staging_table', 'manual__2025-10-22T09:40:06.580597+00:00', '--job-id', '22', '--raw', '--subdir', 'DAGS_FOLDER/main.py', '--cfg-path', '/tmp/tmp1kj26olt']
[2025-10-22T09:40:12.851+0000] {standard_task_runner.py:63} INFO - Started process 4478 to run task
[2025-10-22T09:40:12.872+0000] {standard_task_runner.py:91} INFO - Job 22: Subtask staging_table
[2025-10-22T09:40:13.141+0000] {task_command.py:426} INFO - Running <TaskInstance: update_db.staging_table manual__2025-10-22T09:40:06.580597+00:00 [running]> on host ddff07f854c7
[2025-10-22T09:40:13.521+0000] {taskinstance.py:2648} INFO - Exporting env vars: AIRFLOW_CTX_DAG_EMAIL='gidiboateng200@gmail.com' AIRFLOW_CTX_DAG_OWNER='dataengineers' AIRFLOW_CTX_DAG_ID='update_db' AIRFLOW_CTX_TASK_ID='staging_table' AIRFLOW_CTX_EXECUTION_DATE='2025-10-22T09:40:06.580597+00:00' AIRFLOW_CTX_TRY_NUMBER='1' AIRFLOW_CTX_DAG_RUN_ID='manual__2025-10-22T09:40:06.580597+00:00'
[2025-10-22T09:40:13.526+0000] {taskinstance.py:430} INFO - ::endgroup::
[2025-10-22T09:40:13.624+0000] {base.py:84} INFO - Using connection ID 'postgres_db_yt_elt' for task execution.
[2025-10-22T09:40:13.649+0000] {data_loading.py:12} INFO - Processing file: YT_data_2025-10-22
[2025-10-22T09:40:13.707+0000] {base.py:84} INFO - Using connection ID 'postgres_db_yt_elt' for task execution.
[2025-10-22T09:40:13.749+0000] {base.py:84} INFO - Using connection ID 'postgres_db_yt_elt' for task execution.
[2025-10-22T09:40:13.853+0000] {dataware_house.py:44} ERROR - An error occurred during the update of staging table: column "VIDEO_ID" does not exist
LINE 1: SELECT "VIDEO_ID"FROM staging.yt_api;
               ^

[2025-10-22T09:40:13.856+0000] {taskinstance.py:441} INFO - ::group::Post task execution logs
[2025-10-22T09:40:13.869+0000] {taskinstance.py:2905} ERROR - Task failed with exception
Traceback (most recent call last):
  File "/home/airflow/.local/lib/python3.10/site-packages/airflow/models/taskinstance.py", line 465, in _execute_task
    result = _execute_callable(context=context, **execute_callable_kwargs)
  File "/home/airflow/.local/lib/python3.10/site-packages/airflow/models/taskinstance.py", line 432, in _execute_callable
    return execute_callable(context=context, **execute_callable_kwargs)
  File "/home/airflow/.local/lib/python3.10/site-packages/airflow/models/baseoperator.py", line 401, in wrapper
    return func(self, *args, **kwargs)
  File "/home/airflow/.local/lib/python3.10/site-packages/airflow/decorators/base.py", line 265, in execute
    return_value = super().execute(context)
  File "/home/airflow/.local/lib/python3.10/site-packages/airflow/models/baseoperator.py", line 401, in wrapper
    return func(self, *args, **kwargs)
  File "/home/airflow/.local/lib/python3.10/site-packages/airflow/operators/python.py", line 235, in execute
    return_value = self.execute_callable()
  File "/home/airflow/.local/lib/python3.10/site-packages/airflow/operators/python.py", line 252, in execute_callable
    return self.python_callable(*self.op_args, **self.op_kwargs)
  File "/opt/airflow/dags/datawarehouse/dataware_house.py", line 45, in staging_table
    raise e
  File "/opt/airflow/dags/datawarehouse/dataware_house.py", line 24, in staging_table
    table_ids = get_video_ids(cur, schema)
  File "/opt/airflow/dags/datawarehouse/data_utils.py", line 59, in get_video_ids
    cur.execute(f"""SELECT "VIDEO_ID"FROM {schema}.{table};""")
  File "/home/airflow/.local/lib/python3.10/site-packages/psycopg2/extras.py", line 236, in execute
    return super().execute(query, vars)
psycopg2.errors.UndefinedColumn: column "VIDEO_ID" does not exist
LINE 1: SELECT "VIDEO_ID"FROM staging.yt_api;
               ^

[2025-10-22T09:40:13.938+0000] {taskinstance.py:1206} INFO - Marking task as FAILED. dag_id=update_db, task_id=staging_table, run_id=manual__2025-10-22T09:40:06.580597+00:00, execution_date=20251022T094006, start_date=20251022T094012, end_date=20251022T094013
[2025-10-22T09:40:13.981+0000] {standard_task_runner.py:110} ERROR - Failed to execute job 22 for task staging_table (column "VIDEO_ID" does not exist
LINE 1: SELECT "VIDEO_ID"FROM staging.yt_api;
               ^
; 4478)
[2025-10-22T09:40:14.060+0000] {local_task_job_runner.py:240} INFO - Task exited with return code 1
[2025-10-22T09:40:14.138+0000] {taskinstance.py:3503} INFO - 0 downstream tasks scheduled from follow-on schedule check
[2025-10-22T09:40:14.152+0000] {local_task_job_runner.py:222} INFO - ::endgroup::
