[2025-10-22T10:33:00.856+0000] {local_task_job_runner.py:120} INFO - ::group::Pre task execution logs
[2025-10-22T10:33:00.935+0000] {taskinstance.py:2076} INFO - Dependencies all met for dep_context=non-requeueable deps ti=<TaskInstance: update_db.staging_table manual__2025-10-22T10:32:58.478206+00:00 [queued]>
[2025-10-22T10:33:00.968+0000] {taskinstance.py:2076} INFO - Dependencies all met for dep_context=requeueable deps ti=<TaskInstance: update_db.staging_table manual__2025-10-22T10:32:58.478206+00:00 [queued]>
[2025-10-22T10:33:00.969+0000] {taskinstance.py:2306} INFO - Starting attempt 1 of 1
[2025-10-22T10:33:01.022+0000] {taskinstance.py:2330} INFO - Executing <Task(_PythonDecoratedOperator): staging_table> on 2025-10-22 10:32:58.478206+00:00
[2025-10-22T10:33:01.041+0000] {standard_task_runner.py:63} INFO - Started process 5086 to run task
[2025-10-22T10:33:01.050+0000] {standard_task_runner.py:90} INFO - Running: ['airflow', 'tasks', 'run', 'update_db', 'staging_table', 'manual__2025-10-22T10:32:58.478206+00:00', '--job-id', '35', '--raw', '--subdir', 'DAGS_FOLDER/main.py', '--cfg-path', '/tmp/tmpmhq4weaf']
[2025-10-22T10:33:01.063+0000] {standard_task_runner.py:91} INFO - Job 35: Subtask staging_table
[2025-10-22T10:33:01.255+0000] {task_command.py:426} INFO - Running <TaskInstance: update_db.staging_table manual__2025-10-22T10:32:58.478206+00:00 [running]> on host ddff07f854c7
[2025-10-22T10:33:01.523+0000] {taskinstance.py:2648} INFO - Exporting env vars: AIRFLOW_CTX_DAG_EMAIL='gidiboateng200@gmail.com' AIRFLOW_CTX_DAG_OWNER='dataengineers' AIRFLOW_CTX_DAG_ID='update_db' AIRFLOW_CTX_TASK_ID='staging_table' AIRFLOW_CTX_EXECUTION_DATE='2025-10-22T10:32:58.478206+00:00' AIRFLOW_CTX_TRY_NUMBER='1' AIRFLOW_CTX_DAG_RUN_ID='manual__2025-10-22T10:32:58.478206+00:00'
[2025-10-22T10:33:01.525+0000] {taskinstance.py:430} INFO - ::endgroup::
[2025-10-22T10:33:01.562+0000] {base.py:84} INFO - Using connection ID 'postgres_db_yt_elt' for task execution.
[2025-10-22T10:33:01.572+0000] {data_loading.py:12} INFO - Processing file: YT_data_2025-10-22
[2025-10-22T10:33:01.593+0000] {base.py:84} INFO - Using connection ID 'postgres_db_yt_elt' for task execution.
[2025-10-22T10:33:01.611+0000] {base.py:84} INFO - Using connection ID 'postgres_db_yt_elt' for task execution.
[2025-10-22T10:33:01.629+0000] {dataware_house.py:58} ERROR - An error occurred during the update of staging table: name 'insert_rows' is not defined
[2025-10-22T10:33:01.630+0000] {taskinstance.py:441} INFO - ::group::Post task execution logs
[2025-10-22T10:33:01.632+0000] {taskinstance.py:2905} ERROR - Task failed with exception
Traceback (most recent call last):
  File "/home/airflow/.local/lib/python3.10/site-packages/airflow/models/taskinstance.py", line 465, in _execute_task
    result = _execute_callable(context=context, **execute_callable_kwargs)
  File "/home/airflow/.local/lib/python3.10/site-packages/airflow/models/taskinstance.py", line 432, in _execute_callable
    return execute_callable(context=context, **execute_callable_kwargs)
  File "/home/airflow/.local/lib/python3.10/site-packages/airflow/models/baseoperator.py", line 401, in wrapper
    return func(self, *args, **kwargs)
  File "/home/airflow/.local/lib/python3.10/site-packages/airflow/decorators/base.py", line 265, in execute
    return_value = super().execute(context)
  File "/home/airflow/.local/lib/python3.10/site-packages/airflow/models/baseoperator.py", line 401, in wrapper
    return func(self, *args, **kwargs)
  File "/home/airflow/.local/lib/python3.10/site-packages/airflow/operators/python.py", line 235, in execute
    return_value = self.execute_callable()
  File "/home/airflow/.local/lib/python3.10/site-packages/airflow/operators/python.py", line 252, in execute_callable
    return self.python_callable(*self.op_args, **self.op_kwargs)
  File "/opt/airflow/dags/datawarehouse/dataware_house.py", line 59, in staging_table
    raise e
  File "/opt/airflow/dags/datawarehouse/dataware_house.py", line 40, in staging_table
    insert_rows(cur, conn, schema, row)
NameError: name 'insert_rows' is not defined
[2025-10-22T10:33:01.665+0000] {taskinstance.py:1206} INFO - Marking task as FAILED. dag_id=update_db, task_id=staging_table, run_id=manual__2025-10-22T10:32:58.478206+00:00, execution_date=20251022T103258, start_date=20251022T103300, end_date=20251022T103301
[2025-10-22T10:33:01.705+0000] {standard_task_runner.py:110} ERROR - Failed to execute job 35 for task staging_table (name 'insert_rows' is not defined; 5086)
[2025-10-22T10:33:01.754+0000] {local_task_job_runner.py:240} INFO - Task exited with return code 1
[2025-10-22T10:33:01.834+0000] {taskinstance.py:3503} INFO - 0 downstream tasks scheduled from follow-on schedule check
[2025-10-22T10:33:01.849+0000] {local_task_job_runner.py:222} INFO - ::endgroup::
